<sdf version='1.7'>
  <model name='prueba_jaya'>
    <link name='base_link'>
      <inertial>
        <pose>0.045938 -0.0004 0.043559 0 -0 0</pose>
        <mass>35.8482</mass>
        <inertia>
          <ixx>0.290291</ixx>
          <ixy>0.00440736</ixy>
          <ixz>0.00781017</ixz>
          <iyy>0.176265</iyy>
          <iyz>0.000329552</iyz>
          <izz>0.433436</izz>
        </inertia>
      </inertial>
      <collision name='base_link_collision'>
        <pose>0 0 0 0 -0 0</pose>
        <geometry>
          <mesh>
            <scale>1 1 1</scale>
            <uri>model://prueba_jaya/meshes/base_link.STL</uri>
          </mesh>
        </geometry>
      </collision>
      <collision name='base_link_fixed_joint_lump__camara_link_collision_1'>
        <pose>-0.072415 0.000708 0.234 0 -0 0</pose>
        <geometry>
          <mesh>
            <scale>1 1 1</scale>
            <uri>model://prueba_jaya/meshes/camara_link.STL</uri>
          </mesh>
        </geometry>
      </collision>
      <collision name='base_link_fixed_joint_lump__castor_back_link_collision_2'>
        <pose>-0.126 0 0.00058 0 -0 0</pose>
        <geometry>
          <mesh>
            <scale>1 1 1</scale>
            <uri>model://prueba_jaya/meshes/castor_back_link.STL</uri>
          </mesh>
        </geometry>
      </collision>
      <collision name='base_link_fixed_joint_lump__castor_front_link_collision_3'>
        <pose>0.126 0 0.00058 0 -0 0</pose>
        <geometry>
          <mesh>
            <scale>1 1 1</scale>
            <uri>model://prueba_jaya/meshes/castor_front_link.STL</uri>
          </mesh>
        </geometry>
      </collision>
      <collision name='base_link_fixed_joint_lump__lidar_link_collision_4'>
        <pose>-0.026219 0.001791 0.1385 0 -0 0</pose>
        <geometry>
          <mesh>
            <scale>1 1 1</scale>
            <uri>model://prueba_jaya/meshes/lidar_link.STL</uri>
          </mesh>
        </geometry>
      </collision>
      <visual name='base_link_visual'>
        <pose>0 0 0 0 -0 0</pose>
        <geometry>
          <mesh>
            <scale>1 1 1</scale>
            <uri>model://prueba_jaya/meshes/base_link.STL</uri>
          </mesh>
        </geometry>
      </visual>
      <visual name='base_link_fixed_joint_lump__camara_link_visual_1'>
        <pose>-0.072415 0.000708 0.234 0 -0 0</pose>
        <geometry>
          <mesh>
            <scale>1 1 1</scale>
            <uri>model://prueba_jaya/meshes/camara_link.STL</uri>
          </mesh>
        </geometry>
      </visual>
      <visual name='base_link_fixed_joint_lump__castor_back_link_visual_2'>
        <pose>-0.126 0 0.00058 0 -0 0</pose>
        <geometry>
          <mesh>
            <scale>1 1 1</scale>
            <uri>model://prueba_jaya/meshes/castor_back_link.STL</uri>
          </mesh>
        </geometry>
      </visual>
      <visual name='base_link_fixed_joint_lump__castor_front_link_visual_3'>
        <pose>0.126 0 0.00058 0 -0 0</pose>
        <geometry>
          <mesh>
            <scale>1 1 1</scale>
            <uri>model://prueba_jaya/meshes/castor_front_link.STL</uri>
          </mesh>
        </geometry>
      </visual>
      <visual name='base_link_fixed_joint_lump__lidar_link_visual_4'>
        <pose>-0.026219 0.001791 0.1385 0 -0 0</pose>
        <geometry>
          <mesh>
            <scale>1 1 1</scale>
            <uri>model://prueba_jaya/meshes/lidar_link.STL</uri>
          </mesh>
        </geometry>
      </visual>
    </link>
    <joint name='rueda_derecha_joint' type='revolute'>
      <pose relative_to='base_link'>0 -0.11755 0.023608 1.5708 -0 -3.14159</pose>
      <parent>base_link</parent>
      <child>rueda_derecha_link</child>
      <axis>
        <xyz>0 0 1</xyz>
        <limit>
          <effort>100</effort>
          <velocity>100</velocity>
          <lower>-1e+16</lower>
          <upper>1e+16</upper>
        </limit>
        <dynamics>
          <damping>0.1</damping>
          <friction>0.1</friction>
          <spring_reference>0</spring_reference>
          <spring_stiffness>0</spring_stiffness>
        </dynamics>
      </axis>
    </joint>
    <link name='rueda_derecha_link'>
      <pose relative_to='rueda_derecha_joint'>0 0 0 0 -0 0</pose>
      <inertial>
        <pose>0 0 0 0 -0 0</pose>
        <mass>0.54355</mass>
        <inertia>
          <ixx>0.0001863</ixx>
          <ixy>1.4078e-33</ixy>
          <ixz>-1.0337e-16</ixz>
          <iyy>0.0001863</iyy>
          <iyz>-2.2382e-21</iyz>
          <izz>0.00035222</izz>
        </inertia>
      </inertial>
      <collision name='rueda_derecha_link_collision'>
        <pose>0 0 0 0 -0 0</pose>
        <geometry>
          <mesh>
            <scale>1 1 1</scale>
            <uri>model://prueba_jaya/meshes/rueda_derecha_link.STL</uri>
          </mesh>
        </geometry>
      </collision>
      <visual name='rueda_derecha_link_visual'>
        <pose>0 0 0 0 -0 0</pose>
        <geometry>
          <mesh>
            <scale>1 1 1</scale>
            <uri>model://prueba_jaya/meshes/rueda_derecha_link.STL</uri>
          </mesh>
        </geometry>
      </visual>
    </link>
    <joint name='rueda_izquierda_joint' type='revolute'>
      <pose relative_to='base_link'>0 0.11755 0.023608 1.5708 -0 -3.14159</pose>
      <parent>base_link</parent>
      <child>rueda_izquierda_link</child>
      <axis>
        <xyz>0 0 1</xyz>
        <limit>
          <effort>100</effort>
          <velocity>100</velocity>
          <lower>-1e+16</lower>
          <upper>1e+16</upper>
        </limit>
        <dynamics>
          <damping>0.1</damping>
          <friction>0.1</friction>
          <spring_reference>0</spring_reference>
          <spring_stiffness>0</spring_stiffness>
        </dynamics>
      </axis>
    </joint>
    <link name='rueda_izquierda_link'>
      <pose relative_to='rueda_izquierda_joint'>0 0 0 0 -0 0</pose>
      <inertial>
        <pose>0 0 -0 0 -0 0</pose>
        <mass>0.54355</mass>
        <inertia>
          <ixx>0.0001863</ixx>
          <ixy>-1.3925e-33</ixy>
          <ixz>-1.032e-16</ixz>
          <iyy>0.0001863</iyy>
          <iyz>2.2382e-21</iyz>
          <izz>0.00035222</izz>
        </inertia>
      </inertial>
      <collision name='rueda_izquierda_link_collision'>
        <pose>0 0 0 0 -0 0</pose>
        <geometry>
          <mesh>
            <scale>1 1 1</scale>
            <uri>model://prueba_jaya/meshes/rueda_izquierda_link.STL</uri>
          </mesh>
        </geometry>
      </collision>
      <visual name='rueda_izquierda_link_visual'>
        <pose>0 0 0 0 -0 0</pose>
        <geometry>
          <mesh>
            <scale>1 1 1</scale>
            <uri>model://prueba_jaya/meshes/rueda_izquierda_link.STL</uri>
          </mesh>
        </geometry>
      </visual>
    </link>
  </model>
</sdf>
