<?xml version="1.0"?>
<robot name="prueba_jaya" xmlns:xacro="http://www.ros.org/wiki/xacro">

  <!-- Propiedades Comunes -->
  <xacro:property name="color_silver" value="0.79216 0.81961 0.93333 1" />
  <xacro:property name="color_gray" value="0.74902 0.74902 0.74902 1" />
  <xacro:property name="color_base" value="1 1 1 0.35" />
  <xacro:property name="color_rueda" value="0.53725 0.34902 0.33725 1" />

  <!-- Links -->
  <link name="base_footprint"/>

  <link name="base_link">
    <inertial>
      <origin xyz="0.046344 -0.00040698 0.043458" rpy="0 0 0" />
      <mass value="1.592" />
      <inertia ixx="0.28872" ixy="0.0043751" ixz="0.007308" iyy="0.17123" iyz="0.00033454" izz="0.42993" />
    </inertial>
    <visual>
      <origin xyz="0 0 0" rpy="0 0 0" />
      <geometry>
        <mesh filename="package://romba_description/meshes/base_link.STL" />
      </geometry>
      <material name="">
        <color rgba="${color_base}" />
      </material>
    </visual>
    <collision>
      <origin xyz="0 0 0" rpy="0 0 0" />
      <geometry>
        <mesh filename="package://romba_description/meshes/base_link.STL" />
      </geometry>
    </collision>
  </link>

  <link name="rueda_derecha_link">
    <inertial>
      <origin xyz="0 8.6736E-19 1.3878E-17" rpy="0 0 0" />
      <mass value="0.54355" />
      <inertia ixx="0.0001863" ixy="1.4078E-33" ixz="-1.0337E-16" iyy="0.0001863" iyz="-2.2382E-21" izz="0.00035222" />
    </inertial>
    <visual>
      <origin xyz="0 0 0" rpy="0 0 0" />
      <geometry>
        <mesh filename="package://romba_description/meshes/rueda_derecha_link.STL" />
      </geometry>
      <material name="">
        <color rgba="${color_rueda}" />
      </material>
    </visual>
    <collision>
      <origin xyz="0 0 0" rpy="0 0 0" />
      <geometry>
        <mesh filename="package://romba_description/meshes/rueda_derecha_link.STL" />
      </geometry>
    </collision>
  </link>

  <link name="rueda_izquierda_link">
    <inertial>
      <origin xyz="1.0534E-19 8.6736E-19 -1.3878E-17" rpy="0 0 0" />
      <mass value="0.54355" />
      <inertia ixx="0.0001863" ixy="-1.3925E-33" ixz="-1.032E-16" iyy="0.0001863" iyz="2.2382E-21" izz="0.00035222" />
    </inertial>
    <visual>
      <origin xyz="0 0 0" rpy="0 0 0" />
      <geometry>
        <mesh filename="package://romba_description/meshes/rueda_izquierda_link.STL" />
      </geometry>
      <material name="">
        <color rgba="${color_rueda}" />
      </material>
    </visual>
    <collision>
      <origin xyz="0 0 0" rpy="0 0 0" />
      <geometry>
        <mesh filename="package://romba_description/meshes/rueda_izquierda_link.STL" />
      </geometry>
    </collision>
  </link>

  <link name="castor_front_link">
    <inertial>
      <origin xyz="0 0 0" rpy="0 0 0" />
      <mass value="0.081382" />
      <inertia ixx="5.478E-06" ixy="0" ixz="-2.6151E-38" iyy="5.478E-06" iyz="1.9156E-38" izz="5.478E-06" />
    </inertial>
    <visual>
      <origin xyz="0 0 0" rpy="0 0 0" />
      <geometry>
        <mesh filename="package://romba_description/meshes/castor_front_link.STL" />
      </geometry>
      <material name="">
        <color rgba="${color_rueda}" />
      </material>
    </visual>
    <collision>
      <origin xyz="0 0 0" rpy="0 0 0" />
      <geometry>
        <mesh filename="package://romba_description/meshes/castor_front_link.STL" />
      </geometry>
    </collision>
  </link>

  <link name="castor_back_link">
    <inertial>
      <origin xyz="0 0 0" rpy="0 0 0" />
      <mass value="0.081382" />
      <inertia ixx="5.478E-06" ixy="0" ixz="-2.6151E-38" iyy="5.478E-06" iyz="1.9156E-38" izz="5.478E-06" />
    </inertial>
    <visual>
      <origin xyz="0 0 0" rpy="0 0 0" />
      <geometry>
        <mesh filename="package://romba_description/meshes/castor_back_link.STL" />
      </geometry>
      <material name="">
        <color rgba="${color_rueda}" />
      </material>
    </visual>
    <collision>
      <origin xyz="0 0 0" rpy="0 0 0" />
      <geometry>
        <mesh filename="package://romba_description/meshes/castor_back_link.STL" />
      </geometry>
    </collision>
  </link>

  <link name="lidar_link">
    <inertial>
      <origin xyz="4.1219E-07 -1.3901E-06 0.013915" rpy="0 0 0" />
      <mass value="0.08848" />
      <inertia ixx="1.4384E-05" ixy="1.5173E-07" ixz="-4.0427E-10" iyy="1.4384E-05" iyz="1.3634E-09" izz="1.6345E-05" />
    </inertial>
    <visual>
      <origin xyz="0 0 0" rpy="0 0 0" />
      <geometry>
        <mesh filename="package://romba_description/meshes/lidar_link.STL" />
      </geometry>
      <material name="">
        <color rgba="${color_gray}" />
      </material>
    </visual>
    <collision>
      <origin xyz="0 0 0" rpy="0 0 0" />
      <geometry>
        <mesh filename="package://romba_description/meshes/lidar_link.STL" />
      </geometry>
    </collision>
  </link>

  <link name="camara_link">
    <inertial>
      <origin xyz="0 0 0" rpy="0 0 0" />
      <mass value="0.005" />
      <inertia ixx="1.4384E-05" ixy="1.4384E-05" ixz="1.4384E-05" iyy="1.4384E-05" iyz="1.4384E-05" izz="1.4384E-05" />
    </inertial>
    <visual>
      <origin xyz="0 0 0" rpy="0 0 0" />
      <geometry>
        <mesh filename="package://romba_description/meshes/camara_link.STL" />
      </geometry>
      <material name="">
        <color rgba="1 1 1 1" />
      </material>
    </visual>
    <collision>
      <origin xyz="0 0 0" rpy="0 0 0" />
      <geometry>
        <mesh filename="package://romba_description/meshes/camara_link.STL" />
      </geometry>
    </collision>
  </link>
  
  <link name="imu_link"/>

  <!-- Joints -->
  <joint name="base_joint" type="fixed">
    <origin xyz="0 0 0.01" rpy="0 0 0" />
    <parent link="base_footprint" />
    <child link="base_link" />
  </joint>

  <joint name="rueda_derecha_joint" type="continuous">
    <origin xyz="0 -0.11755 0.023608" rpy="1.5708 0 3.1416" />
    <parent link="base_link" />
    <child link="rueda_derecha_link" />
    <axis xyz="0 0 1" />
    <limit effort="100" velocity="100" />
    <dynamics damping="0.1" friction="0.1" />
  </joint>

  <joint name="rueda_izquierda_joint" type="continuous">
    <origin xyz="0 0.11755 0.023608" rpy="1.5708 0 3.1416" />
    <parent link="base_link" />
    <child link="rueda_izquierda_link" />
    <axis xyz="0 0 1" />
    <limit effort="100" velocity="100" />
    <dynamics damping="0.1" friction="0.1" />
  </joint>

  <joint name="castor_front_joint" type="fixed">
    <origin xyz="0.126 0 0.00058007" rpy="0 0 0" />
    <parent link="base_link" />
    <child link="castor_front_link" />
    <axis xyz="0 0 0" />
    <limit effort="100" velocity="100" />
    <dynamics damping="0.1" friction="0.1" />
  </joint>

  <joint name="castor_back_joint" type="fixed">
    <origin xyz="-0.126 0 0.00058007" rpy="0 0 0" />
    <parent link="base_link" />
    <child link="castor_back_link" />
    <axis xyz="0 0 0" />
    <limit effort="100" velocity="100" />
    <dynamics damping="0.1" friction="0.1" />
  </joint>

  <joint name="lidar_joint" type="fixed">
    <origin xyz="-0.026219 0.0017912 0.1385" rpy="0 0 0" />
    <parent link="base_link" />
    <child link="lidar_link" />
    <axis xyz="0 0 0" />
    <limit effort="100" velocity="100" />
    <dynamics damping="0.1" friction="0.1" />
  </joint>

  <joint name="camara_joint" type="fixed">
    <origin xyz="-0.072415 0.00070842 0.234" rpy="0 0 0" />
    <parent link="base_link" />
    <child link="camara_link" />
    <axis xyz="0 0 0" />
    <limit effort="100" velocity="100" />
    <dynamics damping="0.1" friction="0.1" />
  </joint>

  <!-- IMU Joint -->
  <joint name="imu_joint" type="fixed">
    <parent link="base_link"/>
    <child link="imu_link"/>
    <origin xyz="-0.032 0 0.068" rpy="0 0 0"/>
  </joint>
  
  <!-- Configuration Wheels -->
  <gazebo reference="rueda_derecha_link">
    <mu1>100000.0</mu1>
    <mu2>100000.0</mu2>
    <kp>3000000.0</kp>
    <kd>90.0</kd>
    <minDepth>0.001</minDepth>
    <maxVel>0.1</maxVel>
    <fdir1>1 0 0</fdir1>
    <material>Gazebo/FlatBlack</material>
  </gazebo>

  <gazebo reference="rueda_izquierda_link">
    <mu1>100000.0</mu1>
    <mu2>100000.0</mu2>
    <kp>3000000.0</kp>
    <kd>90.0</kd>
    <minDepth>0.001</minDepth>
    <maxVel>0.1</maxVel>
    <fdir1>1 0 0</fdir1>
    <material>Gazebo/FlatBlack</material>
  </gazebo>
  
  <gazebo reference="castor_front_link">
    <mu1>0.1</mu1>
    <mu2>0.1</mu2>
    <material>Gazebo/FlatBlack</material>
  </gazebo>

  <gazebo reference="castor_back_link">
    <mu1>0.0001</mu1>
    <mu2>0.0001</mu2>
    <material>Gazebo/FlatBlack</material>
  </gazebo>
  
  <!-- Plugin -->
  <gazebo>
    <!-- Plugin control ruedas diferenciales -->
    <plugin name="wheel_drive_controller" filename="libgazebo_ros_diff_drive.so">
      <ros>
        <namespace></namespace>
        <remapping>cmd_vel:=cmd_vel</remapping>
        <remapping>odom:=odom</remapping>
      </ros>
      <update_rate>20</update_rate>
      <left_joint>rueda_izquierda_joint</left_joint>
      <right_joint>rueda_derecha_joint</right_joint>
      <wheel_separation>0.229</wheel_separation>
      <wheel_diameter>0.072</wheel_diameter>
      <max_wheel_torque>10</max_wheel_torque>
      <max_wheel_acceleration>1.0</max_wheel_acceleration>
      <publish_odom>true</publish_odom>
      <publish_odom_tf>true</publish_odom_tf>
      <publish_wheel_tf>true</publish_wheel_tf>
      <odometry_frame>odom</odometry_frame>
      <robot_base_frame>base_footprint</robot_base_frame>
    </plugin>
  </gazebo>

  <!-- GAZEBO LASER -->
  <gazebo reference="lidar_link">
    <material>Gazebo/FlatBlack</material>
    <sensor type="ray" name="lds_lfcd_sensor">
      <pose>0 0 0 0 0 0</pose>
      <always_on>true</always_on>
      <update_rate>10.0</update_rate>
      <visualize>true</visualize>
      <ray>
        <scan>
          <horizontal>
            <samples>360</samples>
            <resolution>1</resolution>
            <min_angle>0.0</min_angle>
            <max_angle>6.28319</max_angle>
          </horizontal>
        </scan>
        <range>
          <min>0.120</min>
          <max>2.0</max>
          <resolution>0.015</resolution>
        </range>
        <noise>
          <type>gaussian</type>
          <mean>0.0</mean>
          <stddev>0.01</stddev>
        </noise>
      </ray>
      <plugin name="gazebo_ros_lds_lfcd_controller" filename="libgazebo_ros_ray_sensor.so">
        <ros>
          <namespace></namespace>
          <remapping>~/out:=scan</remapping>
        </ros>
        <output_type>sensor_msgs/LaserScan</output_type>
      </plugin>
    </sensor>
  </gazebo>
  
  <!-- GAZEBO CAM_LINK -->
  <gazebo reference="camara_link">
      <material>Gazebo/Black</material>
      <sensor name="camera" type="camera">
        <pose> 0 0 0 0 0 0</pose>
        <visualize>true</visualize>
        <update_rate>30</update_rate>
        <camera>
            <horizontal_fov>1.085595</horizontal_fov>
            <image>
                <format>R8G8B8</format>
                <width>640</width>
                <height>480</height>
            </image>
            <clip>
                <near>0.03</near>
                <far>100</far>
            </clip>
        </camera>
        <plugin name="camera_controller" filename="libgazebo_ros_camera.so">
            <frame_name>camara_link</frame_name>
        </plugin>
      </sensor>
      <sensor name="intel_realsense_d435_depth" type="depth">
        <pose> 0 0 0 0 0 0</pose>
        <always_on>true</always_on>
        <update_rate>20</update_rate>
        <camera name="realsense_depth_camera">
        </camera>
        <plugin name="intel_realsense_d435_depth_driver" filename="libgazebo_ros_camera.so">
            <camera_name>intel_realsense_d435_depth</camera_name>
            <frame_name>camara_link</frame_name>
            <hack_baseline>0.07</hack_baseline>
            <min_depth>0.001</min_depth>
          </plugin>
      </sensor>
  </gazebo>
  
  <!-- GAZEBO IMU_LINK -->
  <gazebo reference="imu_link">
    <material>Gazebo/Grey</material>
    <sensor type="imu" name="imu">
      <always_on>true</always_on>
      <update_rate>100.0</update_rate>
      <visualize>true</visualize>
    </sensor>
  </gazebo>

</robot>
