<?xml version="1.0"?>

<robot xmlns:xacro="http://www.ros.org/wiki/xacro" name="romba_final7">

  <!-- Propiedades Comunes -->
  <xacro:property name="color_silver" value="0.79216 0.81961 0.93333 1" />
  <xacro:property name="color_gray" value="0.74902 0.74902 0.74902 1" />

  <!-- Links -->
  <link name="base_footprint"/>

  <link name="base_link">
    <inertial>
      <origin xyz="-0.012852 0.00021377 0.095235" rpy="0 0 0" />
      <mass value="1.0281" />
      <inertia ixx="0.0059108" ixy="9.6296E-06" ixz="2.9882E-05" iyy="0.0040504" iyz="-3.7361E-07" izz="0.0097661" />
    </inertial>
    <visual>
      <origin xyz="0 0 0" rpy="0 0 0" />
      <geometry>
        <mesh filename="package://romba_description/meshes/base_link.STL" />
      </geometry>
      <material name="">
        <color rgba="0.53725 0.34902 0.33725 1" />
      </material>
    </visual>
    <collision>
      <origin xyz="0 0 0" rpy="0 0 0" />
      <geometry>
        <mesh filename="package://romba_description/meshes/base_link.STL" />
      </geometry>
    </collision>
  </link>

  <link name="rueda_derecha_link">
    <inertial>
      <origin xyz="0 -1.3878E-17 0.0075" rpy="0 0 0" />
      <mass value="0.53306" />
      <inertia ixx="0.00018604" ixy="5.9215E-35" ixz="1.7205E-19" iyy="0.00018604" iyz="5.9601E-20" izz="0.00035209" />
    </inertial>
    <visual>
      <origin xyz="0 0 0" rpy="0 0 0" />
      <geometry>
        <mesh filename="package://romba_description/meshes/rueda_derecha_link.STL" />
      </geometry>
      <material name="">
        <color rgba="0.53725 0.34902 0.33725 1" />
      </material>
    </visual>
    <collision>
      <origin xyz="0 0 0" rpy="0 0 0" />
      <geometry>
        <mesh filename="package://romba_description/meshes/rueda_derecha_link.STL" />
      </geometry>
    </collision>
  </link>

  <link name="rueda_izquierda_link">
    <inertial>
      <origin xyz="0 -1.3878E-17 -0.0075" rpy="0 0 0" />
      <mass value="0.53306" />
      <inertia ixx="0.00018604" ixy="-5.5945E-21" ixz="1.2078E-19" iyy="0.00018604" iyz="6.9269E-20" izz="0.00035209" />
    </inertial>
    <visual>
      <origin xyz="0 0 0" rpy="0 0 0" />
      <geometry>
        <mesh filename="package://romba_description/meshes/rueda_izquierda_link.STL" />
      </geometry>
      <material name="">
        <color rgba="0.53725 0.34902 0.33725 1" />
      </material>
    </visual>
    <collision>
      <origin xyz="0 0 0" rpy="0 0 0" />
      <geometry>
        <mesh filename="package://romba_description/meshes/rueda_izquierda_link.STL" />
      </geometry>
    </collision>
  </link>

  <link name="castor_front_link">
    <inertial>
      <origin xyz="0 0 -0.000305158376732312" rpy="0 0 0" />
      <mass value="0.0377583102708451" />
      <inertia ixx="1.71192991486171E-06" ixy="0" ixz="-7.47071207291216E-23" iyy="1.71192991486171E-06" iyz="6.25066770861755E-23" izz="1.93681067303436E-06" />
    </inertial>
    <visual>
      <origin xyz="0 0 0" rpy="0 0 0" />
      <geometry>
        <mesh filename="package://romba_description/meshes/castor_front_link.STL" />
      </geometry>
      <material name="">
        <color rgba="0.537254901960784 0.349019607843137 0.337254901960784 1" />
      </material>
    </visual>
    <collision>
      <origin xyz="0 0 0" rpy="0 0 0" />
      <geometry>
        <mesh filename="package://romba_description/meshes/castor_front_link.STL" />
      </geometry>
    </collision>
  </link>

  <link name="castor_back_link">
    <inertial>
      <origin xyz="-1.3878E-17 -3.4694E-18 -0.00030516" rpy="0 0 0" />
      <mass value="0.037758" />
      <inertia ixx="1.7119E-06" ixy="2.647E-23" ixz="1.1262E-23" iyy="1.7119E-06" iyz="1.6053E-23" izz="1.9368E-06" />
    </inertial>
    <visual>
      <origin xyz="0 0 0" rpy="0 0 0" />
      <geometry>
        <mesh filename="package://romba_description/meshes/castor_back_link.STL" />
      </geometry>
      <material name="">
        <color rgba="0.53725 0.34902 0.33725 1" />
      </material>
    </visual>
    <collision>
      <origin xyz="0 0 0" rpy="0 0 0" />
      <geometry>
        <mesh filename="package://romba_description/meshes/castor_back_link.STL" />
      </geometry>
    </collision>
  </link>

  <link name="camara_link">
    <inertial>
      <origin xyz="0.011556 8.1034E-06 -0.00013612" rpy="0 0 0" />
      <mass value="0.10771" />
      <inertia ixx="7.1119E-05" ixy="-3.5434E-08" ixz="4.9148E-08" iyy="7.6952E-06" iyz="-1.1534E-10" izz="7.0122E-05" />
    </inertial>
    <visual>
      <origin xyz="0 0 0" rpy="0 0 0" />
      <geometry>
        <mesh filename="package://romba_description/meshes/camara_link.STL" />
      </geometry>
      <material name="">
        <color rgba="0.89804 0.91765 0.92941 1" />
      </material>
    </visual>
    <collision>
      <origin xyz="0 0 0" rpy="0 0 0" />
      <geometry>
        <mesh filename="package://romba_description/meshes/camara_link.STL" />
      </geometry>
    </collision>
  </link>

  <link name="lidar_link">
    <inertial>
      <origin xyz="0 0 0" rpy="0 0 0" />
      <mass value="0" />
      <inertia ixx="0" ixy="0" ixz="0" iyy="0" iyz="0" izz="0" />
    </inertial>
    <visual>
      <origin xyz="0 0 0" rpy="0 0 0" />
      <geometry>
        <mesh filename="package://romba_description/meshes/lidar_link.STL" />
      </geometry>
      <material name="">
        <color rgba="1 1 1 1" />
      </material>
    </visual>
    <collision>
      <origin xyz="0 0 0" rpy="0 0 0" />
      <geometry>
        <mesh filename="package://romba_description/meshes/lidar_link.STL" />
      </geometry>
    </collision>
  </link>

  <!-- Joints -->
  <joint name="base_joint" type="fixed">
    <origin xyz="0 0 0.01" rpy="0 0 0" />
    <parent link="base_footprint" />
    <child link="base_link" />
  </joint>

  <joint name="derecha_joint" type="continuous">
    <origin xyz="0.0028919 -0.122 0.018229" rpy="1.5708 0 3.1416" />
    <parent link="base_link" />
    <child link="rueda_derecha_link" />
    <axis xyz="0 0 1" />
    <limit effort="100" velocity="100" />
    <dynamics damping="0.1" friction="0.1" />
  </joint>

  <joint name="izquierda_joint" type="continuous">
    <origin xyz="0.0028919 0.12199 0.018229" rpy="1.5708 0 3.1416" />
    <parent link="base_link" />
    <child link="rueda_izquierda_link" />
    <axis xyz="0 0 1" />
    <limit effort="100" velocity="100" />
    <dynamics damping="0.1" friction="0.1" />
  </joint>

  <joint name="castor_front_joint" type="fixed">
    <origin xyz="0.13178 0.00026847 -0.0077659" rpy="0 0 -0.15476" />
    <parent link="base_link" />
    <child link="castor_front_link" />
    <axis xyz="0 0 0" />
    <limit effort="100" velocity="100" />
    <dynamics damping="0.1" friction="0.1" />
  </joint>

  <joint name="castor_back_joint" type="fixed">
    <origin xyz="-0.11581 0.00019601 -0.0077659" rpy="0 0 -0.15477" />
    <parent link="base_link" />
    <child link="castor_back_link" />
    <axis xyz="0 0 0" />
    <limit effort="100" velocity="100" />
    <dynamics damping="0.1" friction="0.1" />
  </joint>

  <joint name="camara_joint" type="fixed">
    <origin xyz="-0.066 0.0010978 0.22823" rpy="0 0 0" />
    <parent link="base_link" />
    <child link="camara_link" />
    <axis xyz="0 0 0" />
    <limit effort="100" velocity="100" />
    <dynamics damping="0.1" friction="0.1" />
  </joint>

  <joint name="lidar_joint" type="fixed">
    <origin xyz="-0.019804 0.0021806 0.13273" rpy="0 0 0" />
    <parent link="base_link" />
    <child link="lidar_link" />
    <axis xyz="0 0 0" />
    <limit effort="100" velocity="100" />
    <dynamics damping="0.1" friction="0.1" />
  </joint>


 

</robot>
