<?xml version="1.0"?>

<robot xmlns:xacro="http://www.ros.org/wiki/xacro" name="roomba_final3">

  <!-- Propiedades Comunes -->
  <xacro:property name="color_silver" value="0.79216 0.81961 0.93333 1" />
  <xacro:property name="color_gray" value="0.74902 0.74902 0.74902 1" />

  <!-- Links -->
  <link name="base_footprint"/>

  <link name="base_link">
    <inertial>
      <origin xyz="-0.018804 0.0003512 0.1096" rpy="0 0 0" />
      <mass value="0.56609" />
      <inertia ixx="0.0035439" ixy="9.7497E-06" ixz="2.7928E-05" iyy="0.0020993" iyz="-3.4959E-07" izz="0.0054612" />
    </inertial>
    <visual>
      <origin xyz="0 0 0" rpy="0 0 0" />
      <geometry>
        <mesh filename="package://romba_description/meshes/base_link.STL" />
      </geometry>
      <material name="">
        <color rgba="${color_silver}" />
      </material>
    </visual>
    <collision>
      <origin xyz="0 0 0" rpy="0 0 0" />
      <geometry>
        <mesh filename="package://romba_description/meshes/base_link.STL" />
      </geometry>
    </collision>
  </link>

  <link name="rueda_izquierda_link">
    <inertial>
      <origin xyz="0 0 -0.0075" rpy="0 0 0" />
      <mass value="0.059894" />
      <inertia ixx="2.0903E-05" ixy="-6.286E-22" ixz="-1.3571E-20" iyy="2.0903E-05" iyz="-7.7831E-21" izz="3.956E-05" />
    </inertial>
    <visual>
      <origin xyz="0 0 0" rpy="0 0 0" />
      <geometry>
        <mesh filename="package://romba_description/meshes/rueda_izquierda_link.STL" />
      </geometry>
      <material name="">
        <color rgba="${color_gray}" />
      </material>
    </visual>
    <collision>
      <origin xyz="0 0 0" rpy="0 0 0" />
      <geometry>
        <mesh filename="package://romba_description/meshes/rueda_izquierda_link.STL" />
      </geometry>
    </collision>
  </link>

  <link name="rueda_derecha_link">
    <inertial>
      <origin xyz="2.7756E-17 -2.7756E-17 0.0075" rpy="0 0 0" />
      <mass value="0.059894" />
      <inertia ixx="2.0903E-05" ixy="7.6014E-36" ixz="-1.9331E-20" iyy="2.0903E-05" iyz="-5.4394E-21" izz="3.956E-05" />
    </inertial>
    <visual>
      <origin xyz="0 0 0" rpy="0 0 0" />
      <geometry>
        <mesh filename="package://romba_description/meshes/rueda_derecha_link.STL" />
      </geometry>
      <material name="">
        <color rgba="${color_gray}" />
      </material>
    </visual>
    <collision>
      <origin xyz="0 0 0" rpy="0 0 0" />
      <geometry>
        <mesh filename="package://romba_description/meshes/rueda_derecha_link.STL" />
      </geometry>
    </collision>
  </link>

  <link name="rueda_loca1_link">
    <inertial>
      <origin xyz="1.1781E-05 -6.3594E-06 -0.00030486" rpy="0 0 0" />
      <mass value="0.0042425" />
      <inertia ixx="1.9239E-07" ixy="-2.0329E-11" ixz="-9.7454E-10" iyy="1.9236E-07" iyz="5.2606E-10" izz="2.1757E-07" />
    </inertial>
    <visual>
      <origin xyz="0 0 0" rpy="0 0 0" />
      <geometry>
        <mesh filename="package://romba_description/meshes/rueda_loca1_link.STL" />
      </geometry>
      <material name="">
        <color rgba="${color_gray}" />
      </material>
    </visual>
    <collision>
      <origin xyz="0 0 0" rpy="0 0 0" />
      <geometry>
        <mesh filename="package://romba_description/meshes/rueda_loca1_link.STL" />
      </geometry>
    </collision>
  </link>

  <link name="rueda_loca_link">
    <inertial>
      <origin xyz="0 2.0503E-13 -0.00030516" rpy="0 0 0" />
      <mass value="0.0042425" />
      <inertia ixx="1.9235E-07" ixy="-3.1019E-25" ixz="1.1357E-23" iyy="1.9235E-07" iyz="-1.6977E-17" izz="2.1762E-07" />
    </inertial>
    <visual>
      <origin xyz="0 0 0" rpy="0 0 0" />
      <geometry>
        <mesh filename="package://romba_description/meshes/rueda_loca_link.STL" />
      </geometry>
      <material name="">
        <color rgba="${color_gray}" />
      </material>
    </visual>
    <collision>
      <origin xyz="0 0 0" rpy="0 0 0" />
      <geometry>
        <mesh filename="package://romba_description/meshes/rueda_loca_link.STL" />
      </geometry>
    </collision>
  </link>

  <link name="camara_link">
    <inertial>
      <origin xyz="0.011556 8.1034E-06 -0.00013612" rpy="0 0 0" />
      <mass value="0.039891" />
      <inertia ixx="2.634E-05" ixy="-1.3124E-08" ixz="1.8203E-08" iyy="2.8501E-06" iyz="-4.272E-11" izz="2.5971E-05" />
    </inertial>
    <visual>
      <origin xyz="0 0 0" rpy="0 0 0" />
      <geometry>
        <mesh filename="package://romba_description/meshes/cam_link.STL" />
      </geometry>
      <material name="">
        <color rgba="${color_silver}" />
      </material>
    </visual>
    <collision>
      <origin xyz="0 0 0" rpy="0 0 0" />
      <geometry>
        <mesh filename="package://romba_description/meshes/cam_link.STL" />
      </geometry>
    </collision>
  </link>

  <link name="lidar_link">
    <inertial>
      <origin xyz="4.1439E-07 -1.3901E-06 0.013915" rpy="0 0 0" />
      <mass value="0.03277" />
      <inertia ixx="5.3274E-06" ixy="5.6195E-08" ixz="-1.4962E-10" iyy="5.3275E-06" iyz="5.0497E-10" izz="6.0536E-06" />
    </inertial>
    <visual>
      <origin xyz="0 0 0" rpy="0 0 0" />
      <geometry>
        <mesh filename="package://romba_description/meshes/lidar_link.STL" />
      </geometry>
      <material name="">
        <color rgba="0.99608 0.99608 1 1" />
      </material>
    </visual>
    <collision>
      <origin xyz="0 0 0" rpy="0 0 0" />
      <geometry>
        <mesh filename="package://romba_description/meshes/lidar_link.STL" />
      </geometry>
    </collision>
  </link>

  <!-- Joints -->
  <joint name="base_joint" type="fixed">
    <origin xyz="0 0 0.01" rpy="0 0 0" />
    <parent link="base_footprint" />
    <child link="base_link" />
  </joint>

  <joint name="rueda_izquierda_joint" type="continuous">
    <origin xyz="0.0028919 0.12199 0.021229" rpy="-1.5708 0 0" />
    <parent link="base_link" />
    <child link="rueda_izquierda_link" />
    <axis xyz="0 0 1" />
    <limit effort="100" velocity="100" />
    <dynamics damping="0.1" friction="0.1" />
  </joint>

  <joint name="rueda_derecha_joint" type="continuous">
    <origin xyz="0.0028919 -0.122 0.021229" rpy="-1.5708 0 0" />
    <parent link="base_link" />
    <child link="rueda_derecha_link" />
    <axis xyz="0 0 1" />
    <limit effort="100" velocity="100" />
    <dynamics damping="0.1" friction="0.1" />
  </joint>

  <joint name="rueda_loca1_joint" type="fixed">
    <origin xyz="-0.10948 2.2157E-05 -0.0047667" rpy="0 0 0" />
    <parent link="base_link" />
    <child link="rueda_loca1_link" />
    <axis xyz="0 0 0" />
    <limit effort="1000" velocity="1000" />
    <dynamics damping="0.1" friction="0.1" />
  </joint>

  <joint name="rueda_loca_joint" type="fixed">
    <origin xyz="0.12957 3.8976E-05 -0.0047674" rpy="0 0 0.0079511" />
    <parent link="base_link" />
    <child link="rueda_loca_link" />
    <axis xyz="0 0 0" />
    <limit effort="100" velocity="100" />
    <dynamics damping="0.1" friction="0.1" />
  </joint>

  <joint name="camara_joint" type="fixed">
    <origin xyz="-0.065999 0.0010978 0.22823" rpy="0 0 0" />
    <parent link="base_link" />
    <child link="camara_link" />
    <axis xyz="0 0 0" />
    <dynamics damping="0.1" friction="0.1" />
  </joint>

  <joint name="laser_joint" type="fixed">
    <origin xyz="-0.019804 0.0021806 0.13273" rpy="0 0 0" />
    <parent link="base_link" />
    <child link="lidar_link" />
    <axis xyz="0 0 0" />
    <dynamics damping="0.1" friction="0.1" />
  </joint>


 


 

</robot>
