<sdf version='1.7'>
  <model name='roomba_jaya_v1'>
    <link name='base_link'>
      <inertial>
        <pose>-0.009861 0.000296 0.095638 0 -0 0</pose>
        <mass>1.05245</mass>
        <inertia>
          <ixx>0.0064608</ixx>
          <ixy>-3.42058e-06</ixy>
          <ixz>0.000378286</ixz>
          <iyy>0.00667453</iyy>
          <iyz>-9.8896e-06</iyz>
          <izz>0.00863765</izz>
        </inertia>
      </inertial>
      <collision name='base_link_collision'>
        <pose>0 0 0 0 -0 0</pose>
        <geometry>
          <mesh>
            <scale>1 1 1</scale>
            <uri>model://roomba_jaya_v1/meshes/base_link.STL</uri>
          </mesh>
        </geometry>
      </collision>
      <collision name='base_link_fixed_joint_lump__camara_link_collision_1'>
        <pose>-0.045307 0 0.20223 0 -0 0</pose>
        <geometry>
          <mesh>
            <scale>1 1 1</scale>
            <uri>model://roomba_jaya_v1/meshes/camara_link.STL</uri>
          </mesh>
        </geometry>
      </collision>
      <collision name='base_link_fixed_joint_lump__castor_back_link_collision_2'>
        <pose>-0.12241 0 -0.005122 0 -0 0</pose>
        <geometry>
          <mesh>
            <scale>1 1 1</scale>
            <uri>model://roomba_jaya_v1/meshes/castor_back_link.STL</uri>
          </mesh>
        </geometry>
      </collision>
      <collision name='base_link_fixed_joint_lump__castor_front_link_collision_3'>
        <pose>0.12959 0 -0.005122 0 -0 0</pose>
        <geometry>
          <mesh>
            <scale>1 1 1</scale>
            <uri>model://roomba_jaya_v1/meshes/castor_front_link.STL</uri>
          </mesh>
        </geometry>
      </collision>
      <collision name='base_link_fixed_joint_lump__lidar_link_collision_4'>
        <pose>0.001055 0.00423 0.10673 0 -0 0</pose>
        <geometry>
          <mesh>
            <scale>1 1 1</scale>
            <uri>model://roomba_jaya_v1/meshes/lidar_link.STL</uri>
          </mesh>
        </geometry>
      </collision>
      <visual name='base_link_visual'>
        <pose>0 0 0 0 -0 0</pose>
        <geometry>
          <mesh>
            <scale>1 1 1</scale>
            <uri>model://roomba_jaya_v1/meshes/base_link.STL</uri>
          </mesh>
        </geometry>
      </visual>
      <visual name='base_link_fixed_joint_lump__camara_link_visual_1'>
        <pose>-0.045307 0 0.20223 0 -0 0</pose>
        <geometry>
          <mesh>
            <scale>1 1 1</scale>
            <uri>model://roomba_jaya_v1/meshes/camara_link.STL</uri>
          </mesh>
        </geometry>
      </visual>
      <visual name='base_link_fixed_joint_lump__castor_back_link_visual_2'>
        <pose>-0.12241 0 -0.005122 0 -0 0</pose>
        <geometry>
          <mesh>
            <scale>1 1 1</scale>
            <uri>model://roomba_jaya_v1/meshes/castor_back_link.STL</uri>
          </mesh>
        </geometry>
      </visual>
      <visual name='base_link_fixed_joint_lump__castor_front_link_visual_3'>
        <pose>0.12959 0 -0.005122 0 -0 0</pose>
        <geometry>
          <mesh>
            <scale>1 1 1</scale>
            <uri>model://roomba_jaya_v1/meshes/castor_front_link.STL</uri>
          </mesh>
        </geometry>
      </visual>
      <visual name='base_link_fixed_joint_lump__lidar_link_visual_4'>
        <pose>0.001055 0.00423 0.10673 0 -0 0</pose>
        <geometry>
          <mesh>
            <scale>1 1 1</scale>
            <uri>model://roomba_jaya_v1/meshes/lidar_link.STL</uri>
          </mesh>
        </geometry>
      </visual>
    </link>
    <joint name='rueda_derecha_joint' type='revolute'>
      <pose relative_to='base_link'>0.004125 -0.11845 0.020249 1.5708 -0 -3.14159</pose>
      <parent>base_link</parent>
      <child>rueda_derecha_link</child>
      <axis>
        <xyz>0 0 1</xyz>
        <limit>
          <effort>100</effort>
          <velocity>100</velocity>
          <lower>-1e+16</lower>
          <upper>1e+16</upper>
        </limit>
        <dynamics>
          <damping>0.1</damping>
          <friction>0.1</friction>
          <spring_reference>0</spring_reference>
          <spring_stiffness>0</spring_stiffness>
        </dynamics>
      </axis>
    </joint>
    <link name='rueda_derecha_link'>
      <pose relative_to='rueda_derecha_joint'>0 0 0 0 -0 0</pose>
      <inertial>
        <pose>0 0 0 0 -0 0</pose>
        <mass>0.54355</mass>
        <inertia>
          <ixx>0.0001863</ixx>
          <ixy>1.4695e-22</ixy>
          <ixz>-2.1869e-13</ixz>
          <iyy>0.0001863</iyy>
          <iyz>-1.1148e-13</iyz>
          <izz>0.00035222</izz>
        </inertia>
      </inertial>
      <collision name='rueda_derecha_link_collision'>
        <pose>0 0 0 0 -0 0</pose>
        <geometry>
          <mesh>
            <scale>1 1 1</scale>
            <uri>model://roomba_jaya_v1/meshes/rueda_derecha_link.STL</uri>
          </mesh>
        </geometry>
      </collision>
      <visual name='rueda_derecha_link_visual'>
        <pose>0 0 0 0 -0 0</pose>
        <geometry>
          <mesh>
            <scale>1 1 1</scale>
            <uri>model://roomba_jaya_v1/meshes/rueda_derecha_link.STL</uri>
          </mesh>
        </geometry>
      </visual>
    </link>
    <joint name='rueda_izquierda_joint' type='revolute'>
      <pose relative_to='base_link'>0.004125 0.11843 0.020249 1.5708 -0 -3.14159</pose>
      <parent>base_link</parent>
      <child>rueda_izquierda_link</child>
      <axis>
        <xyz>0 0 1</xyz>
        <limit>
          <effort>100</effort>
          <velocity>100</velocity>
          <lower>-1e+16</lower>
          <upper>1e+16</upper>
        </limit>
        <dynamics>
          <damping>0.1</damping>
          <friction>0.1</friction>
          <spring_reference>0</spring_reference>
          <spring_stiffness>0</spring_stiffness>
        </dynamics>
      </axis>
    </joint>
    <link name='rueda_izquierda_link'>
      <pose relative_to='rueda_izquierda_joint'>0 0 0 0 -0 0</pose>
      <inertial>
        <pose>0 0 0 0 -0 0</pose>
        <mass>0.54355</mass>
        <inertia>
          <ixx>0.0001863</ixx>
          <ixy>-1.1556e-26</ixy>
          <ixz>2.1869e-13</ixz>
          <iyy>0.0001863</iyy>
          <iyz>-8.79e-18</iyz>
          <izz>0.00035222</izz>
        </inertia>
      </inertial>
      <collision name='rueda_izquierda_link_collision'>
        <pose>0 0 0 0 -0 0</pose>
        <geometry>
          <mesh>
            <scale>1 1 1</scale>
            <uri>model://roomba_jaya_v1/meshes/rueda_izquierda_link.STL</uri>
          </mesh>
        </geometry>
      </collision>
      <visual name='rueda_izquierda_link_visual'>
        <pose>0 0 0 0 -0 0</pose>
        <geometry>
          <mesh>
            <scale>1 1 1</scale>
            <uri>model://roomba_jaya_v1/meshes/rueda_izquierda_link.STL</uri>
          </mesh>
        </geometry>
      </visual>
    </link>
  </model>
</sdf>
