<?xml version="1.0" encoding="utf-8"?>
<!-- This URDF was automatically created by SolidWorks to URDF Exporter! Originally created by Stephen Brawner (brawner@gmail.com) 
     Commit Version: 1.6.0-4-g7f85cfe  Build Version: 1.6.7995.38578
     For more information, please see http://wiki.ros.org/sw_urdf_exporter -->
<robot
  name="roomba_jaya">
  <link
    name="base_link">
    <inertial>
      <origin
        xyz="-0.00859158753499085 -9.05568164151463E-05 0.0872890863781433"
        rpy="0 0 0" />
      <mass
        value="0.751837307136149" />
      <inertia
        ixx="0.00414996657164725"
        ixy="7.71718694368022E-07"
        ixz="4.74212613028038E-06"
        iyy="0.00292467094495166"
        iyz="-1.0354956289207E-08"
        izz="0.0070301062223736" />
    </inertial>
    <visual>
      <origin
        xyz="0 0 0"
        rpy="0 0 0" />
      <geometry>
        <mesh
          filename="package://roomba_jaya/meshes/base_link.STL" />
      </geometry>
      <material
        name="">
        <color
          rgba="1 1 1 0.35" />
      </material>
    </visual>
    <collision>
      <origin
        xyz="0 0 0"
        rpy="0 0 0" />
      <geometry>
        <mesh
          filename="package://roomba_jaya/meshes/base_link.STL" />
      </geometry>
    </collision>
  </link>
  <link
    name="rueda_derecha_link">
    <inertial>
      <origin
        xyz="3.747E-16 4.3368E-18 0.0075"
        rpy="0 0 0" />
      <mass
        value="0.54355" />
      <inertia
        ixx="0.0001863"
        ixy="6.0661E-33"
        ixz="8.2961E-18"
        iyy="0.0001863"
        iyz="1.0791E-19"
        izz="0.00035222" />
    </inertial>
    <visual>
      <origin
        xyz="0 0 0"
        rpy="0 0 0" />
      <geometry>
        <mesh
          filename="package://roomba_jaya/meshes/rueda_derecha_link.STL" />
      </geometry>
      <material
        name="">
        <color
          rgba="0.53725 0.34902 0.33725 1" />
      </material>
    </visual>
    <collision>
      <origin
        xyz="0 0 0"
        rpy="0 0 0" />
      <geometry>
        <mesh
          filename="package://roomba_jaya/meshes/rueda_derecha_link.STL" />
      </geometry>
    </collision>
  </link>
  <joint
    name="derecha_joint"
    type="continuous">
    <origin
      xyz="0.0068533 -0.12201 0.020207"
      rpy="1.5708 1.5708 0" />
    <parent
      link="base_link" />
    <child
      link="rueda_derecha_link" />
    <axis
      xyz="0 0 1" />
    <limit
      effort="100"
      velocity="100" />
    <dynamics
      damping="0.1"
      friction="0.1" />
  </joint>
  <link
    name="rueda_izquierda_link">
    <inertial>
      <origin
        xyz="-5.0395E-12 1.7347E-18 -0.0075"
        rpy="0 0 0" />
      <mass
        value="0.54355" />
      <inertia
        ixx="0.0001863"
        ixy="-3.9477E-29"
        ixz="1.1149E-13"
        iyy="0.0001863"
        iyz="-5.7637E-20"
        izz="0.00035222" />
    </inertial>
    <visual>
      <origin
        xyz="0 0 0"
        rpy="0 0 0" />
      <geometry>
        <mesh
          filename="package://roomba_jaya/meshes/rueda_izquierda_link.STL" />
      </geometry>
      <material
        name="">
        <color
          rgba="0.53725 0.34902 0.33725 1" />
      </material>
    </visual>
    <collision>
      <origin
        xyz="0 0 0"
        rpy="0 0 0" />
      <geometry>
        <mesh
          filename="package://roomba_jaya/meshes/rueda_izquierda_link.STL" />
      </geometry>
    </collision>
  </link>
  <joint
    name="izquierda_joint"
    type="continuous">
    <origin
      xyz="0.006881 0.12199 0.020249"
      rpy="1.5708 1.5708 0" />
    <parent
      link="base_link" />
    <child
      link="rueda_izquierda_link" />
    <axis
      xyz="0 0 1" />
    <limit
      effort="100"
      velocity="100" />
    <dynamics
      damping="0.1"
      friction="0.1" />
  </joint>
  <link
    name="castor_front_link">
    <inertial>
      <origin
        xyz="0 -3.2526E-19 1.3878E-17"
        rpy="0 0 0" />
      <mass
        value="0.04476" />
      <inertia
        ixx="2.0225E-06"
        ixy="-8.3522E-39"
        ixz="1.8655E-30"
        iyy="2.0225E-06"
        iyz="5.8298E-32"
        izz="2.0225E-06" />
    </inertial>
    <visual>
      <origin
        xyz="0 0 0"
        rpy="0 0 0" />
      <geometry>
        <mesh
          filename="package://roomba_jaya/meshes/castor_front_link.STL" />
      </geometry>
      <material
        name="">
        <color
          rgba="0.53725 0.34902 0.33725 1" />
      </material>
    </visual>
    <collision>
      <origin
        xyz="0 0 0"
        rpy="0 0 0" />
      <geometry>
        <mesh
          filename="package://roomba_jaya/meshes/castor_front_link.STL" />
      </geometry>
    </collision>
  </link>
  <joint
    name="castor_front_joint"
    type="fixed">
    <origin
      xyz="0.12959 0 -0.0051221"
      rpy="0 0 0" />
    <parent
      link="base_link" />
    <child
      link="castor_front_link" />
    <axis
      xyz="0 0 0" />
    <limit
      effort="100"
      velocity="100" />
    <dynamics
      damping="0.1"
      friction="0.1" />
  </joint>
  <link
    name="castor_back_link">
    <inertial>
      <origin
        xyz="-2.7756E-17 2.1684E-19 0"
        rpy="0 0 0" />
      <mass
        value="0.04476" />
      <inertia
        ixx="2.0225E-06"
        ixy="-2.4321E-24"
        ixz="5.8684E-24"
        iyy="2.0225E-06"
        iyz="-7.1433E-23"
        izz="2.0225E-06" />
    </inertial>
    <visual>
      <origin
        xyz="0 0 0"
        rpy="0 0 0" />
      <geometry>
        <mesh
          filename="package://roomba_jaya/meshes/castor_back_link.STL" />
      </geometry>
      <material
        name="">
        <color
          rgba="0.53725 0.34902 0.33725 1" />
      </material>
    </visual>
    <collision>
      <origin
        xyz="0 0 0"
        rpy="0 0 0" />
      <geometry>
        <mesh
          filename="package://roomba_jaya/meshes/castor_back_link.STL" />
      </geometry>
    </collision>
  </link>
  <joint
    name="castor_back_joint"
    type="fixed">
    <origin
      xyz="-0.1045 0 -0.0051221"
      rpy="0 0 0" />
    <parent
      link="base_link" />
    <child
      link="castor_back_link" />
    <axis
      xyz="0 0 0" />
    <limit
      effort="100"
      velocity="100" />
    <dynamics
      damping="0.1"
      friction="0.1" />
  </joint>
  <link
    name="camara_link">
    <inertial>
      <origin
        xyz="1.1261E-05 -0.00013612 0.011556"
        rpy="0 0 0" />
      <mass
        value="0.039891" />
      <inertia
        ixx="2.8501E-06"
        ixy="-3.7742E-11"
        ixz="-6.705E-09"
        iyy="2.5971E-05"
        iyz="1.8203E-08"
        izz="2.634E-05" />
    </inertial>
    <visual>
      <origin
        xyz="0 0 0"
        rpy="0 0 0" />
      <geometry>
        <mesh
          filename="package://roomba_jaya/meshes/camara_link.STL" />
      </geometry>
      <material
        name="">
        <color
          rgba="0.79216 0.81961 0.93333 1" />
      </material>
    </visual>
    <collision>
      <origin
        xyz="0 0 0"
        rpy="0 0 0" />
      <geometry>
        <mesh
          filename="package://roomba_jaya/meshes/camara_link.STL" />
      </geometry>
    </collision>
  </link>
  <joint
    name="camara_joint"
    type="fixed">
    <origin
      xyz="-0.045307 0 0.20223"
      rpy="1.5708 0 1.5708" />
    <parent
      link="base_link" />
    <child
      link="camara_link" />
    <axis
      xyz="0 0 0" />
    <limit
      effort="100"
      velocity="100" />
    <dynamics
      damping="0.1"
      friction="0.1" />
  </joint>
  <link
    name="lidar_link">
    <inertial>
      <origin
        xyz="0 0 0"
        rpy="0 0 0" />
      <mass
        value="0.004" />
      <inertia
        ixx="1E-06"
        ixy="4E-06"
        ixz="5E-07"
        iyy="1E-08"
        iyz="1.2E-10"
        izz="1.3E-12" />
    </inertial>
    <visual>
      <origin
        xyz="0 0 0"
        rpy="0 0 0" />
      <geometry>
        <mesh
          filename="package://roomba_jaya/meshes/lidar_link.STL" />
      </geometry>
      <material
        name="">
        <color
          rgba="1 1 1 1" />
      </material>
    </visual>
    <collision>
      <origin
        xyz="0 0 0"
        rpy="0 0 0" />
      <geometry>
        <mesh
          filename="package://roomba_jaya/meshes/lidar_link.STL" />
      </geometry>
    </collision>
  </link>
  <joint
    name="lidar_joint"
    type="fixed">
    <origin
      xyz="0.0010554 0.0042304 0.10673"
      rpy="0 0 0" />
    <parent
      link="base_link" />
    <child
      link="lidar_link" />
    <axis
      xyz="0 0 0" />
    <limit
      effort="100"
      velocity="100" />
    <dynamics
      damping="0.1"
      friction="0.1" />
  </joint>
</robot>