<sdf version='1.7'>
  <model name='rumba'>
    <link name='base_link'>
      <inertial>
        <pose>0.015593 -0.000466 0.038553 0 -0 0</pose>
        <mass>0.629393</mass>
        <inertia>
          <ixx>0.004188</ixx>
          <ixy>1.15281e-05</ixy>
          <ixz>-0.000244232</ixz>
          <iyy>0.00283399</iyy>
          <iyz>6.15184e-06</iyz>
          <izz>0.00560042</izz>
        </inertia>
      </inertial>
      <collision name='base_link_collision'>
        <pose>0 0 0 0 -0 0</pose>
        <geometry>
          <mesh>
            <scale>1 1 1</scale>
            <uri>model://romba_description/meshes/base_link.STL</uri>
          </mesh>
        </geometry>
      </collision>
      <collision name='base_link_fixed_joint_lump__base_camara_Link_collision_1'>
        <pose>0.083407 -0.001196 0.057 -3.14159 -0 -1.57107</pose>
        <geometry>
          <mesh>
            <scale>1 1 1</scale>
            <uri>model://romba_description/meshes/base_camara_Link.STL</uri>
          </mesh>
        </geometry>
      </collision>
      <collision name='base_link_fixed_joint_lump__camara_Link_collision_2'>
        <pose>0.061223 -0.00108 0.1495 1.5708 0 -1.57107</pose>
        <geometry>
          <mesh>
            <scale>1 1 1</scale>
            <uri>model://romba_description/meshes/camara_Link.STL</uri>
          </mesh>
        </geometry>
      </collision>
      <collision name='base_link_fixed_joint_lump__lidar_Link_collision_3'>
        <pose>0.015028 -0.002163 0.054 0 -0 0</pose>
        <geometry>
          <mesh>
            <scale>1 1 1</scale>
            <uri>model://romba_description/meshes/lidar_Link.STL</uri>
          </mesh>
        </geometry>
      </collision>
      <visual name='base_link_visual'>
        <pose>0 0 0 0 -0 0</pose>
        <geometry>
          <mesh>
            <scale>1 1 1</scale>
            <uri>model://romba_description/meshes/base_link.STL</uri>
          </mesh>
        </geometry>
      </visual>
      <visual name='base_link_fixed_joint_lump__base_camara_Link_visual_1'>
        <pose>0.083407 -0.001196 0.057 -3.14159 -0 -1.57107</pose>
        <geometry>
          <mesh>
            <scale>1 1 1</scale>
            <uri>model://romba_description/meshes/base_camara_Link.STL</uri>
          </mesh>
        </geometry>
      </visual>
      <visual name='base_link_fixed_joint_lump__camara_Link_visual_2'>
        <pose>0.061223 -0.00108 0.1495 1.5708 0 -1.57107</pose>
        <geometry>
          <mesh>
            <scale>1 1 1</scale>
            <uri>model://romba_description/meshes/camara_Link.STL</uri>
          </mesh>
        </geometry>
      </visual>
      <visual name='base_link_fixed_joint_lump__lidar_Link_visual_3'>
        <pose>0.015028 -0.002163 0.054 0 -0 0</pose>
        <geometry>
          <mesh>
            <scale>1 1 1</scale>
            <uri>model://romba_description/meshes/lidar_Link.STL</uri>
          </mesh>
        </geometry>
      </visual>
    </link>
    <joint name='Rueda_loca_joint' type='revolute'>
      <pose relative_to='base_link'>-0.13436 -0.010606 -0.086201 1.5708 -0 -3.14159</pose>
      <parent>base_link</parent>
      <child>Rueda_loca_Link</child>
      <axis>
        <xyz>0 0 -1</xyz>
        <limit>
          <lower>-1e+16</lower>
          <upper>1e+16</upper>
        </limit>
        <dynamics>
          <damping>0.1</damping>
          <friction>0.1</friction>
          <spring_reference>0</spring_reference>
          <spring_stiffness>0</spring_stiffness>
        </dynamics>
      </axis>
    </joint>
    <link name='Rueda_loca_Link'>
      <pose relative_to='Rueda_loca_joint'>0 0 0 0 -0 0</pose>
      <inertial>
        <pose>-1.8e-05 0.003329 0.010585 0 -0 0</pose>
        <mass>0.00502922</mass>
        <inertia>
          <ixx>2.27249e-07</ixx>
          <ixy>1.66997e-30</ixy>
          <ixz>-1.00974e-26</ixz>
          <iyy>2.27249e-07</iyy>
          <iyz>0</iyz>
          <izz>2.27249e-07</izz>
        </inertia>
      </inertial>
      <collision name='Rueda_loca_Link_collision'>
        <pose>0 0 0 0 -0 0</pose>
        <geometry>
          <mesh>
            <scale>1 1 1</scale>
            <uri>model://romba_description/meshes/Rueda_loca_Link.STL</uri>
          </mesh>
        </geometry>
      </collision>
      <visual name='Rueda_loca_Link_visual'>
        <pose>0 0 0 0 -0 0</pose>
        <geometry>
          <mesh>
            <scale>1 1 1</scale>
            <uri>model://romba_description/meshes/Rueda_loca_Link.STL</uri>
          </mesh>
        </geometry>
      </visual>
    </link>
    <joint name='left_wheel_joint' type='revolute'>
      <pose relative_to='base_link'>-0.007668 0.12202 -0.0575 1.5708 0 3.14159</pose>
      <parent>base_link</parent>
      <child>left_wheel_Link</child>
      <axis>
        <xyz>0 0 -1</xyz>
        <limit>
          <lower>-1e+16</lower>
          <upper>1e+16</upper>
        </limit>
        <dynamics>
          <damping>0.1</damping>
          <friction>0.1</friction>
          <spring_reference>0</spring_reference>
          <spring_stiffness>0</spring_stiffness>
        </dynamics>
      </axis>
    </joint>
    <link name='left_wheel_Link'>
      <pose relative_to='left_wheel_joint'>0 0 0 0 -0 0</pose>
      <inertial>
        <pose>0 0 -0.0075 0 -0 0</pose>
        <mass>0.0610726</mass>
        <inertia>
          <ixx>2.09326e-05</ixx>
          <ixy>1.01836e-34</ixy>
          <ixz>-3.58068e-20</ixz>
          <iyy>2.09326e-05</iyy>
          <iyz>-5.41917e-20</iyz>
          <izz>3.9575e-05</izz>
        </inertia>
      </inertial>
      <collision name='left_wheel_Link_collision'>
        <pose>0 0 0 0 -0 0</pose>
        <geometry>
          <mesh>
            <scale>1 1 1</scale>
            <uri>model://romba_description/meshes/left_wheel_Link.STL</uri>
          </mesh>
        </geometry>
      </collision>
      <visual name='left_wheel_Link_visual'>
        <pose>0 0 0 0 -0 0</pose>
        <geometry>
          <mesh>
            <scale>1 1 1</scale>
            <uri>model://romba_description/meshes/left_wheel_Link.STL</uri>
          </mesh>
        </geometry>
      </visual>
    </link>
    <joint name='right_wheel_joint' type='revolute'>
      <pose relative_to='base_link'>-0.007668 -0.12198 -0.0575 1.5708 0 3.14159</pose>
      <parent>base_link</parent>
      <child>right_wheel_Link</child>
      <axis>
        <xyz>0 0 -1</xyz>
        <limit>
          <lower>-1e+16</lower>
          <upper>1e+16</upper>
        </limit>
        <dynamics>
          <damping>0.1</damping>
          <friction>0.1</friction>
          <spring_reference>0</spring_reference>
          <spring_stiffness>0</spring_stiffness>
        </dynamics>
      </axis>
    </joint>
    <link name='right_wheel_Link'>
      <pose relative_to='right_wheel_joint'>0 0 0 0 -0 0</pose>
      <inertial>
        <pose>0 -0 0.0075 0 -0 0</pose>
        <mass>0.0610726</mass>
        <inertia>
          <ixx>2.09326e-05</ixx>
          <ixy>6.35275e-22</ixy>
          <ixz>-4.17768e-20</ixz>
          <iyy>2.09326e-05</iyy>
          <iyz>-5.65832e-20</iyz>
          <izz>3.9575e-05</izz>
        </inertia>
      </inertial>
      <collision name='right_wheel_Link_collision'>
        <pose>0 0 0 0 -0 0</pose>
        <geometry>
          <mesh>
            <scale>1 1 1</scale>
            <uri>model://romba_description/meshes/right_wheel_Link.STL</uri>
          </mesh>
        </geometry>
      </collision>
      <visual name='right_wheel_Link_visual'>
        <pose>0 0 0 0 -0 0</pose>
        <geometry>
          <mesh>
            <scale>1 1 1</scale>
            <uri>model://romba_description/meshes/right_wheel_Link.STL</uri>
          </mesh>
        </geometry>
      </visual>
    </link>
  </model>
</sdf>
